<?xml version="1.0"?>
<robot xmlns:xacro="http://www.ros.org/wiki/xacro">

  <xacro:macro name="steering_wheel">

    <link name="steering_wheel">
      <inertial>
        <mass value="1.0"/>
        <inertia ixx="0.14583300" ixy="0.0" ixz="0.0" iyy="0.14583300" iyz="0.0" izz="0.125"/>
      </inertial>
      <visual>
        <origin xyz="0 0 0" rpy="1.302101 0 0"/>
        <geometry>
          <mesh filename="package://vehicle_description/meshes/steering_wheel.obj" scale="0.01 0.01 0.01"/>
        </geometry>
      </visual>
    </link>

    <joint name="steering_joint" type="continuous">
      <origin xyz="0 0 1.4" rpy="-1.302101 0  ${pi/2}"/>
      <parent link="${base_link}"/>
      <child link="steering_wheel"/>
      <axis xyz="0 0 1"/>
      <limit lower="-7.85" upper="7.85" effort="10000000" velocity="1000000"/>
    </joint>
    
  </xacro:macro>

</robot>
