<?xml version="1.0"?>
<robot name="wheel" xmlns:xacro="http://www.ros.org/wiki/xacro">

  <xacro:macro name="cylinder_inertia" params="m r h">
    <inertia  ixx="${m*(3*r*r+h*h)/12}" ixy = "0" ixz = "0"
              iyy="${m*(3*r*r+h*h)/12}" iyz = "0"
              izz="${m*r*r/2}" />
  </xacro:macro>

  <xacro:macro name="axle" params="lr"> <!-- lr: left, right -> only for front wheels -->
    <link name="${lr}_axle">

      <visual>
        <origin xyz="0 0 0" rpy="${pi/2} 0 0" />
        <geometry>
          <cylinder length="${axle_length}" radius="${axle_radius}" />
        </geometry>
        <material name="black" />
      </visual>

      <inertial>
        <mass value="1"/>
        <origin xyz="0 0 0"/>
        <inertia ixx="0.004" ixy="0.0" ixz="0.0" iyy="0.004" iyz="0.0" izz="0.004"/>
      </inertial>
    </link>

    <joint name="front_${lr}_steer_joint" type="revolute">
      <parent link="${base_link}"/>
      <child link="${lr}_axle"/>

      <xacro:if value="${lr == 'right'}">
        <origin xyz="${la} ${-axle_x_pos} 0" rpy="0 0 ${pi}" />
      </xacro:if>

      <xacro:if value="${lr == 'left'}">
        <origin xyz="${la} ${axle_x_pos} 0" rpy="0 0 0" />
      </xacro:if>

      <axis xyz="0 0 1"/>
      <limit lower="-0.8727" upper="0.8727" effort="10000000" velocity="1000000"/>
      <dynamics damping="100"/>
    </joint>


  </xacro:macro>

  <xacro:macro name="wheel" params="fb lr parent "> <!--fb : front, back ; lr: left, right -->

    <gazebo reference="${fb}_${lr}_wheel">
      <mu1>${mu1}</mu1>
      <mu2>${mu2}</mu2>
      <minDepth>${minDepth}</minDepth>
      <kp>${kp}</kp>
      <kd  value="1.0" />
      <fdir1 value="1 0 0"/>
      <!--material>Gazebo/Grey</material-->
      <turnGravityOff>false</turnGravityOff>
    </gazebo>

    <link name="${fb}_${lr}_wheel">

      <visual>
        <xacro:if value="${mesh_mode == 1}">
          <origin xyz="0 0 ${-wheel_radius}" rpy="0 0 0" />
          <geometry>
            <mesh filename="package://vehicle_description/meshes/wheel.dae" scale=" ${scale_factor} ${scale_factor} ${scale_factor}"/>
          </geometry>
        </xacro:if>
        <xacro:if value="${mesh_mode == 0}">
          <origin xyz="0 0 0" rpy="${pi/2} 0 0" />
          <geometry>
            <cylinder length="${wheel_width}" radius="${wheel_radius}" />
          </geometry>
        </xacro:if>
      </visual>

      <collision>
        <origin xyz="0 0 0" rpy="${pi/2} 0 0 " />
        <geometry>
          <cylinder length="${wheel_width}" radius="${wheel_radius}" />
        </geometry>
        <!--selfCollide>false</selfCollide-->
      </collision>

      <inertial>
        <mass value="${wheel_mass}" />
        <origin xyz="0 0 0 "  rpy="${pi/2} 0 0" />
        <xacro:cylinder_inertia  m="${wheel_mass}" r="${wheel_radius}" h="${wheel_width}" />
      </inertial>

    </link>

    <joint name="${fb}_${lr}_wheel_joint" type="continuous">
      <parent link="${parent}"/>
      <child link="${fb}_${lr}_wheel"/>

      <xacro:if value="${fb == 'front'}">
        <origin xyz="0 ${axle_length} 0" rpy="0 0 0" />
      </xacro:if>

      <xacro:if value="${fb == 'rear'}">
        <xacro:if value="${lr == 'right'}">
          <origin xyz="${-lb} ${-wheel_base} 0" rpy="0 0 ${pi}" />
        </xacro:if>

        <xacro:if value="${lr == 'left'}">
          <origin xyz="${-lb} ${wheel_base} 0" rpy="0 0 0" />
        </xacro:if>
      </xacro:if>

      <axis xyz="0 1 0" rpy="0  0" />
      <limit effort="100" velocity="100"/>
      <joint_properties damping="0.0" friction="0.0"/>
    </joint>

  </xacro:macro>

</robot>
